<mujoco>
<body pos="0 0 0.25" childclass="scissor">
	<freejoint/>
	<geom name="knob" mesh="knob"/>
	<geom name="scb" mesh="scb"/>
	<geom name="scb_handle" mesh="scb_handle" contype="0" conaffinity="0"/>
	<geom class="scissor_contact" name="scb_handle000" mesh="scb_handle000"/>
	<geom class="scissor_contact" name="scb_handle001" mesh="scb_handle001"/>
	<geom class="scissor_contact" name="scb_handle002" mesh="scb_handle002"/>
	<geom class="scissor_contact" name="scb_handle003" mesh="scb_handle003"/>
	<geom class="scissor_contact" name="scb_handle004" mesh="scb_handle004"/>
	<geom class="scissor_contact" name="scb_handle005" mesh="scb_handle005"/>
	<geom class="scissor_contact" name="scb_handle006" mesh="scb_handle006"/>
	<geom class="scissor_contact" name="scb_handle007" mesh="scb_handle007"/>
	<geom class="scissor_contact" name="scb_handle008" mesh="scb_handle008"/>
	<geom class="scissor_contact" name="scb_handle009" mesh="scb_handle009"/>
	<body>
		<joint name="knob" axis="1 0 0"/>
		<geom name="sct" mesh="sct"/>
		<geom name="sct_handle" mesh="sct_handle" contype="0" conaffinity="0"/>
		<geom class="scissor_contact" name="sct_handle000" mesh="sct_handle000"/>
		<geom class="scissor_contact" name="sct_handle001" mesh="sct_handle001"/>
		<geom class="scissor_contact" name="sct_handle002" mesh="sct_handle002"/>
		<geom class="scissor_contact" name="sct_handle003" mesh="sct_handle003"/>
		<geom class="scissor_contact" name="sct_handle004" mesh="sct_handle004"/>
		<geom class="scissor_contact" name="sct_handle005" mesh="sct_handle005"/>
		<geom class="scissor_contact" name="sct_handle006" mesh="sct_handle006"/>
		<geom class="scissor_contact" name="sct_handle007" mesh="sct_handle007"/>
		<geom class="scissor_contact" name="sct_handle008" mesh="sct_handle008"/>
		<geom class="scissor_contact" name="sct_handle009" mesh="sct_handle009"/>
	</body>
</body>
</mujoco>